 * Serving Flask app "server.py" (lazy loading)
 * Environment: production
   WARNING: Do not use the development server in a production environment.
   Use a production WSGI server instead.
 * Debug mode: on
 * Running on http://127.0.0.1:5000/ (Press CTRL+C to quit)
 * Restarting with stat
 * Debugger is active!
 * Debugger PIN: 912-644-241
 * Serving Flask app "server.py" (lazy loading)
 * Environment: production
   WARNING: Do not use the development server in a production environment.
   Use a production WSGI server instead.
 * Debug mode: on
 * Running on http://127.0.0.1:5000/ (Press CTRL+C to quit)
 * Restarting with stat
 * Debugger is active!
 * Debugger PIN: 912-644-241
 * Serving Flask app "server.py" (lazy loading)
 * Environment: production
   WARNING: Do not use the development server in a production environment.
   Use a production WSGI server instead.
 * Debug mode: on
 * Running on http://127.0.0.1:5000/ (Press CTRL+C to quit)
 * Restarting with stat
 * Debugger is active!
 * Debugger PIN: 912-644-241
Failed to import the site module
Traceback (most recent call last):
  File "/Users/Amanda/GitHub/scout/scout/bin/../lib/python3.5/site.py", line 69, in <module>
    import __builtin__ as builtins
  File "<frozen importlib._bootstrap>", line 969, in _find_and_load
  File "<frozen importlib._bootstrap>", line 954, in _find_and_load_unlocked
  File "<frozen importlib._bootstrap>", line 896, in _find_spec
  File "<frozen importlib._bootstrap_external>", line 1136, in find_spec
  File "<frozen importlib._bootstrap_external>", line 1110, in _get_spec
  File "<frozen importlib._bootstrap_external>", line 1218, in find_spec
  File "<frozen importlib._bootstrap_external>", line 75, in _path_stat
KeyboardInterrupt
Traceback (most recent call last):
  File "/Users/Amanda/GitHub/scout/scout/bin/flask", line 7, in <module>
    from flask.cli import main
  File "/Users/Amanda/GitHub/scout/scout/lib/python3.5/site-packages/flask/__init__.py", line 17, in <module>
    from werkzeug.exceptions import abort
  File "/Users/Amanda/GitHub/scout/scout/lib/python3.5/site-packages/werkzeug/__init__.py", line 151, in <module>
    __import__('werkzeug.exceptions')
  File "/Users/Amanda/GitHub/scout/scout/lib/python3.5/site-packages/werkzeug/exceptions.py", line 71, in <module>
    from werkzeug.wrappers import Response
  File "/Users/Amanda/GitHub/scout/scout/lib/python3.5/site-packages/werkzeug/wrappers.py", line 27, in <module>
    from werkzeug.http import HTTP_STATUS_CODES, \
  File "/Users/Amanda/GitHub/scout/scout/lib/python3.5/site-packages/werkzeug/http.py", line 23, in <module>
    from email.utils import parsedate_tz
  File "/Library/Frameworks/Python.framework/Versions/3.5/lib/python3.5/email/utils.py", line 40, in <module>
    from email.charset import Charset
  File "/Library/Frameworks/Python.framework/Versions/3.5/lib/python3.5/email/charset.py", line 17, in <module>
    from email import errors
  File "<frozen importlib._bootstrap>", line 969, in _find_and_load
  File "<frozen importlib._bootstrap>", line 954, in _find_and_load_unlocked
  File "<frozen importlib._bootstrap>", line 896, in _find_spec
  File "<frozen importlib._bootstrap_external>", line 1136, in find_spec
  File "<frozen importlib._bootstrap_external>", line 1110, in _get_spec
  File "<frozen importlib._bootstrap_external>", line 1245, in find_spec
  File "<frozen importlib._bootstrap_external>", line 53, in _path_join
  File "<frozen importlib._bootstrap_external>", line 53, in <listcomp>
KeyboardInterrupt
 * Serving Flask app "server.py" (lazy loading)
 * Environment: production
   WARNING: Do not use the development server in a production environment.
   Use a production WSGI server instead.
 * Debug mode: on
 * Running on http://127.0.0.1:5000/ (Press CTRL+C to quit)
 * Restarting with stat
 * Debugger is active!
 * Debugger PIN: 912-644-241
 * Detected change in '/Users/Amanda/GitHub/scout/scout/lib/python3.5/site-packages/z3/z3rcf.py', reloading
 * Restarting with stat
Fatal Python error: Py_Initialize: can't initialize sys standard streams
OSError: [Errno 9] Bad file descriptor

Current thread 0x000000010190e380 (most recent call first):
